Workbook

Sheet Orders
A1: Row ID | B1: Order ID | C1: Order Date | D1: Ship Date | E1: Ship Mode | F1: Customer ID | G1: Customer Name | H1: Segment | I1: Country | J1: City | K1: State | L1: Postal Code | M1: Region | N1: Product ID | O1: Category | P1: Sub-Category | Q1: Product Name | R1: Sales | S1: Quantity | T1: Discount | U1: Profit | V1: Order Year | W1: Order Month | X1: Month Number | Y1: Profit Margin | Z1: Shipping Days
A2: 1 | B2: CA-2016-152156 | C2: 42682 | D2: 42685 | E2: Second Class | F2: CG-12520 | G2: Claire Gute | H2: Consumer | I2: United States | J2: Henderson | K2: Kentucky | L2: 42420 | M2: South | N2: FUR-BO-10001798 | O2: Furniture | P2: Bookcases | Q2: Bush Somerset Collection Bookcase | R2: 261.96 | S2: 2 | T2: 0 | U2: 41.9136 | V2: =YEAR(Orders!$C2) -> 2016 | W2: =TEXT(Orders!$C2,"mmm") -> Nov | X2: =MONTH(Orders!$C2) -> 11 | Y2: =IFERROR(Orders!$U2/Orders!$R2,0) -> 0.16 | Z2: =Orders!$D2-Orders!$C2 -> 3
A3: 2 | B3: CA-2016-152156 | C3: 42682 | D3: 42685 | E3: Second Class | F3: CG-12520 | G3: Claire Gute | H3: Consumer | I3: United States | J3: Henderson | K3: Kentucky | L3: 42420 | M3: South | N3: FUR-CH-10000454 | O3: Furniture | P3: Chairs | Q3: Hon Deluxe Fabric Upholstered Stacking Chairs, Rounded Back | R3: 731.94 | S3: 3 | T3: 0 | U3: 219.582 | V3: =YEAR(Orders!$C3) -> 2016 | W3: =TEXT(Orders!$C3,"mmm") -> Nov | X3: =MONTH(Orders!$C3) -> 11 | Y3: =IFERROR(Orders!$U3/Orders!$R3,0) -> 0.3 | Z3: =Orders!$D3-Orders!$C3 -> 3
A4: 3 | B4: CA-2016-138688 | C4: 42533 | D4: 42537 | E4: Second Class | F4: DV-13045 | G4: Darrin Van Huff | H4: Corporate | I4: United States | J4: Los Angeles | K4: California | L4: 90036 | M4: West | N4: OFF-LA-10000240 | O4: Office Supplies | P4: Labels | Q4: Self-Adhesive Address Labels for Typewriters by Universal | R4: 14.62 | S4: 2 | T4: 0 | U4: 6.8714 | V4: =YEAR(Orders!$C4) -> 2016 | W4: =TEXT(Orders!$C4,"mmm") -> Jun | X4: =MONTH(Orders!$C4) -> 6 | Y4: =IFERROR(Orders!$U4/Orders!$R4,0) -> 0.47 | Z4: =Orders!$D4-Orders!$C4 -> 4
A5: 4 | B5: US-2015-108966 | C5: 42288 | D5: 42295 | E5: Standard Class | F5: SO-20335 | G5: Sean O'Donnell | H5: Consumer | I5: United States | J5: Fort Lauderdale | K5: Florida | L5: 33311 | M5: South | N5: FUR-TA-10000577 | O5: Furniture | P5: Tables | Q5: Bretford CR4500 Series Slim Rectangular Table | R5: 957.5775 | S5: 5 | T5: 0.45 | U5: -383.031 | V5: =YEAR(Orders!$C5) -> 2015 | W5: =TEXT(Orders!$C5,"mmm") -> Oct | X5: =MONTH(Orders!$C5) -> 10 | Y5: =IFERROR(Orders!$U5/Orders!$R5,0) -> -0.4 | Z5: =Orders!$D5-Orders!$C5 -> 7
A6: 5 | B6: US-2015-108966 | C6: 42288 | D6: 42295 | E6: Standard Class | F6: SO-20335 | G6: Sean O'Donnell | H6: Consumer | I6: United States | J6: Fort Lauderdale | K6: Florida | L6: 33311 | M6: South | N6: OFF-ST-10000760 | O6: Office Supplies | P6: Storage | Q6: Eldon Fold 'N Roll Cart System | R6: 22.368 | S6: 2 | T6: 0.2 | U6: 2.5164 | V6: =YEAR(Orders!$C6) -> 2015 | W6: =TEXT(Orders!$C6,"mmm") -> Oct | X6: =MONTH(Orders!$C6) -> 10 | Y6: =IFERROR(Orders!$U6/Orders!$R6,0) -> 0.1125 | Z6: =Orders!$D6-Orders!$C6 -> 7
A7: 6 | B7: CA-2014-115812 | C7: 41799 | D7: 41804 | E7: Standard Class | F7: BH-11710 | G7: Brosina Hoffman | H7: Consumer | I7: United States | J7: Los Angeles | K7: California | L7: 90032 | M7: West | N7: FUR-FU-10001487 | O7: Furniture | P7: Furnishings | Q7: Eldon Expressions Wood and Plastic Desk Accessories, Cherry Wood | R7: 48.86 | S7: 7 | T7: 0 | U7: 14.1694 | V7: =YEAR(Orders!$C7) -> 2014 | W7: =TEXT(Orders!$C7,"mmm") -> Jun | X7: =MONTH(Orders!$C7) -> 6 | Y7: =IFERROR(Orders!$U7/Orders!$R7,0) -> 0.29 | Z7: =Orders!$D7-Orders!$C7 -> 5
A8: 7 | B8: CA-2014-115812 | C8: 41799 | D8: 41804 | E8: Standard Class | F8: BH-11710 | G8: Brosina Hoffman | H8: Consumer | I8: United States | J8: Los Angeles | K8: California | L8: 90032 | M8: West | N8: OFF-AR-10002833 | O8: Office Supplies | P8: Art | Q8: Newell 322 | R8: 7.28 | S8: 4 | T8: 0 | U8: 1.9656 | V8: =YEAR(Orders!$C8) -> 2014 | W8: =TEXT(Orders!$C8,"mmm") -> Jun | X8: =MONTH(Orders!$C8) -> 6 | Y8: =IFERROR(Orders!$U8/Orders!$R8,0) -> 0.27 | Z8: =Orders!$D8-Orders!$C8 -> 5
A9: 8 | B9: CA-2014-115812 | C9: 41799 | D9: 41804 | E9: Standard Class | F9: BH-11710 | G9: Brosina Hoffman | H9: Consumer | I9: United States | J9: Los Angeles | K9: California | L9: 90032 | M9: West | N9: TEC-PH-10002275 | O9: Technology | P9: Phones | Q9: Mitel 5320 IP Phone VoIP phone | R9: 907.152 | S9: 6 | T9: 0.2 | U9: 90.7152 | V9: =YEAR(Orders!$C9) -> 2014 | W9: =TEXT(Orders!$C9,"mmm") -> Jun | X9: =MONTH(Orders!$C9) -> 6 | Y9: =IFERROR(Orders!$U9/Orders!$R9,0) -> 0.1 | Z9: =Orders!$D9-Orders!$C9 -> 5
A10: 9 | B10: CA-2014-115812 | C10: 41799 | D10: 41804 | E10: Standard Class | F10: BH-11710 | G10: Brosina Hoffman | H10: Consumer | I10: United States | J10: Los Angeles | K10: California | L10: 90032 | M10: West | N10: OFF-BI-10003910 | O10: Office Supplies | P10: Binders | Q10: DXL Angle-View Binders with Locking Rings by Samsill | R10: 18.504 | S10: 3 | T10: 0.2 | U10: 5.7825 | V10: =YEAR(Orders!$C10) -> 2014 | W10: =TEXT(Orders!$C10,"mmm") -> Jun | X10: =MONTH(Orders!$C10) -> 6 | Y10: =IFERROR(Orders!$U10/Orders!$R10,0) -> 0.3125 | Z10: =Orders!$D10-Orders!$C10 -> 5
A11: 10 | B11: CA-2014-115812 | C11: 41799 | D11: 41804 | E11: Standard Class | F11: BH-11710 | G11: Brosina Hoffman | H11: Consumer | I11: United States | J11: Los Angeles | K11: California | L11: 90032 | M11: West | N11: OFF-AP-10002892 | O11: Office Supplies | P11: Appliances | Q11: Belkin F5C206VTEL 6 Outlet Surge | R11: 114.9 | S11: 5 | T11: 0 | U11: 34.47 | V11: =YEAR(Orders!$C11) -> 2014 | W11: =TEXT(Orders!$C11,"mmm") -> Jun | X11: =MONTH(Orders!$C11) -> 6 | Y11: =IFERROR(Orders!$U11/Orders!$R11,0) -> 0.3 | Z11: =Orders!$D11-Orders!$C11 -> 5
A12: 11 | B12: CA-2014-115812 | C12: 41799 | D12: 41804 | E12: Standard Class | F12: BH-11710 | G12: Brosina Hoffman | H12: Consumer | I12: United States | J12: Los Angeles | K12: California | L12: 90032 | M12: West | N12: FUR-TA-10001539 | O12: Furniture | P12: Tables | Q12: Chromcraft Rectangular Conference Tables | R12: 1706.184 | S12: 9 | T12: 0.2 | U12: 85.3092 | V12: =YEAR(Orders!$C12) -> 2014 | W12: =TEXT(Orders!$C12,"mmm") -> Jun | X12: =MONTH(Orders!$C12) -> 6 | Y12: =IFERROR(Orders!$U12/Orders!$R12,0) -> 0.05 | Z12: =Orders!$D12-Orders!$C12 -> 5
A13: 12 | B13: CA-2014-115812 | C13: 41799 | D13: 41804 | E13: Standard Class | F13: BH-11710 | G13: Brosina Hoffman | H13: Consumer | I13: United States | J13: Los Angeles | K13: California | L13: 90032 | M13: West | N13: TEC-PH-10002033 | O13: Technology | P13: Phones | Q13: Konftel 250 Conference phone - Charcoal black | R13: 911.424 | S13: 4 | T13: 0.2 | U13: 68.3568 | V13: =YEAR(Orders!$C13) -> 2014 | W13: =TEXT(Orders!$C13,"mmm") -> Jun | X13: =MONTH(Orders!$C13) -> 6 | Y13: =IFERROR(Orders!$U13/Orders!$R13,0) -> 0.075 | Z13: =Orders!$D13-Orders!$C13 -> 5
... A2235: 2234 | B2235: CA-2015-123232 | C2235: 42352 | D2235: 42354 | E2235: Second Class | F2235: DJ-13630 | G2235: Doug Jacobs | H2235: Consumer | I2235: United States | J2235: Portland | K2235: Oregon | L2235: 97206 | M2235: West | N2235: TEC-PH-10001051 | O2235: Technology | P2235: Phones | Q2235: HTC One | R2235: 319.968 | S2235: 4 | T2235: 0.2 | U2235: 35.9964 | V2235: =YEAR(Orders!$C2235) -> 2015 | W2235: =TEXT(Orders!$C2235,"mmm") -> Dec | X2235: =MONTH(Orders!$C2235) -> 12 | Y2235: =IFERROR(Orders!$U2235/Orders!$R2235,0) -> 0.1125 | Z2235: =Orders!$D2235-Orders!$C2235 -> 2
A2236: 2235 | B2236: CA-2017-104066 | C2236: 43074 | D2236: 43079 | E2236: Standard Class | F2236: QJ-19255 | G2236: Quincy Jones | H2236: Corporate | I2236: United States | J2236: Burlington | K2236: Vermont | L2236: 05408 | M2236: East | N2236: TEC-AC-10001013 | O2236: Technology | P2236: Accessories | Q2236: Logitech ClearChat Comfort/USB Headset H390 | R2236: 205.03 | S2236: 7 | T2236: 0 | U2236: 67.6599 | V2236: =YEAR(Orders!$C2236) -> 2017 | W2236: =TEXT(Orders!$C2236,"mmm") -> Dec | X2236: =MONTH(Orders!$C2236) -> 12 | Y2236: =IFERROR(Orders!$U2236/Orders!$R2236,0) -> 0.33 | Z2236: =Orders!$D2236-Orders!$C2236 -> 5
A2237: 2236 | B2237: CA-2015-145849 | C2237: 42262 | D2237: 42264 | E2237: Second Class | F2237: CT-11995 | G2237: Carol Triggs | H2237: Consumer | I2237: United States | J2237: Indianapolis | K2237: Indiana | L2237: 46203 | M2237: Central | N2237: OFF-ST-10000025 | O2237: Office Supplies | P2237: Storage | Q2237: Fellowes Stor/Drawer Steel Plus Storage Drawers | R2237: 190.86 | S2237: 2 | T2237: 0 | U2237: 11.4516 | V2237: =YEAR(Orders!$C2237) -> 2015 | W2237: =TEXT(Orders!$C2237,"mmm") -> Sep | X2237: =MONTH(Orders!$C2237) -> 9 | Y2237: =IFERROR(Orders!$U2237/Orders!$R2237,0) -> 0.06 | Z2237: =Orders!$D2237-Orders!$C2237 -> 2
A2238: 2237 | B2238: CA-2015-145849 | C2238: 42262 | D2238: 42264 | E2238: Second Class | F2238: CT-11995 | G2238: Carol Triggs | H2238: Consumer | I2238: United States | J2238: Indianapolis | K2238: Indiana | L2238: 46203 | M2238: Central | N2238: OFF-AR-10000817 | O2238: Office Supplies | P2238: Art | Q2238: Manco Dry-Lighter Erasable Highlighter | R2238: 24.32 | S2238: 8 | T2238: 0 | U2238: 8.2688 | V2238: =YEAR(Orders!$C2238) -> 2015 | W2238: =TEXT(Orders!$C2238,"mmm") -> Sep | X2238: =MONTH(Orders!$C2238) -> 9 | Y2238: =IFERROR(Orders!$U2238/Orders!$R2238,0) -> 0.34 | Z2238: =Orders!$D2238-Orders!$C2238 -> 2
A2239: 2238 | B2239: CA-2016-122322 | C2239: 42566 | D2239: 42572 | E2239: Standard Class | F2239: RH-19510 | G2239: Rick Huthwaite | H2239: Home Office | I2239: United States | J2239: Provo | K2239: Utah | L2239: 84604 | M2239: West | N2239: OFF-SU-10000952 | O2239: Office Supplies | P2239: Supplies | Q2239: Fiskars Home & Office Scissors | R2239: 44.4 | S2239: 5 | T2239: 0 | U2239: 12.432 | V2239: =YEAR(Orders!$C2239) -> 2016 | W2239: =TEXT(Orders!$C2239,"mmm") -> Jul | X2239: =MONTH(Orders!$C2239) -> 7 | Y2239: =IFERROR(Orders!$U2239/Orders!$R2239,0) -> 0.28 | Z2239: =Orders!$D2239-Orders!$C2239 -> 6
A2240: 2239 | B2240: CA-2017-166849 | C2240: 42845 | D2240: 42851 | E2240: Standard Class | F2240: SJ-20125 | G2240: Sanjit Jacobs | H2240: Home Office | I2240: United States | J2240: Chicago | K2240: Illinois | L2240: 60610 | M2240: Central | N2240: FUR-FU-10004597 | O2240: Furniture | P2240: Furnishings | Q2240: Eldon Cleatmat Chair Mats for Medium Pile Carpets | R2240: 44.4 | S2240: 2 | T2240: 0.6 | U2240: -52.17 | V2240: =YEAR(Orders!$C2240) -> 2017 | W2240: =TEXT(Orders!$C2240,"mmm") -> Apr | X2240: =MONTH(Orders!$C2240) -> 4 | Y2240: =IFERROR(Orders!$U2240/Orders!$R2240,0) -> -1.175 | Z2240: =Orders!$D2240-Orders!$C2240 -> 6
A2241: 2240 | B2241: CA-2016-146633 | C2241: 42689 | D2241: 42691 | E2241: Second Class | F2241: TG-21310 | G2241: Toby Gnade | H2241: Consumer | I2241: United States | J2241: Los Angeles | K2241: California | L2241: 90049 | M2241: West | N2241: OFF-BI-10003527 | O2241: Office Supplies | P2241: Binders | Q2241: Fellowes PB500 Electric Punch Plastic Comb Binding Machine with Manual Bind | R2241: 1016.792 | S2241: 1 | T2241: 0.2 | U2241: 381.297 | V2241: =YEAR(Orders!$C2241) -> 2016 | W2241: =TEXT(Orders!$C2241,"mmm") -> Nov | X2241: =MONTH(Orders!$C2241) -> 11 | Y2241: =IFERROR(Orders!$U2241/Orders!$R2241,0) -> 0.375 | Z2241: =Orders!$D2241-Orders!$C2241 -> 2
A2242: 2241 | B2242: CA-2016-146633 | C2242: 42689 | D2242: 42691 | E2242: Second Class | F2242: TG-21310 | G2242: Toby Gnade | H2242: Consumer | I2242: United States | J2242: Los Angeles | K2242: California | L2242: 90049 | M2242: West | N2242: OFF-BI-10002982 | O2242: Office Supplies | P2242: Binders | Q2242: Avery Self-Adhesive Photo Pockets for Polaroid Photos | R2242: 38.136 | S2242: 7 | T2242: 0.2 | U2242: 13.3476 | V2242: =YEAR(Orders!$C2242) -> 2016 | W2242: =TEXT(Orders!$C2242,"mmm") -> Nov | X2242: =MONTH(Orders!$C2242) -> 11 | Y2242: =IFERROR(Orders!$U2242/Orders!$R2242,0) -> 0.35 | Z2242: =Orders!$D2242-Orders!$C2242 -> 2
A2243: 2242 | B2243: US-2016-126893 | C2243: 42700 | D2243: 42705 | E2243: Standard Class | F2243: CT-11995 | G2243: Carol Triggs | H2243: Consumer | I2243: United States | J2243: Philadelphia | K2243: Pennsylvania | L2243: 19134 | M2243: East | N2243: TEC-PH-10004165 | O2243: Technology | P2243: Phones | Q2243: Mitel MiVoice 5330e IP Phone | R2243: 494.982 | S2243: 3 | T2243: 0.4 | U2243: -115.4958 | V2243: =YEAR(Orders!$C2243) -> 2016 | W2243: =TEXT(Orders!$C2243,"mmm") -> Nov | X2243: =MONTH(Orders!$C2243) -> 11 | Y2243: =IFERROR(Orders!$U2243/Orders!$R2243,0) -> -0.23333333 | Z2243: =Orders!$D2243-Orders!$C2243 -> 5
A2244: 2243 | B2244: CA-2017-103380 | C2244: 43060 | D2244: 43064 | E2244: Standard Class | F2244: BF-11005 | G2244: Barry Franz | H2244: Home Office | I2244: United States | J2244: Pasadena | K2244: California | L2244: 91104 | M2244: West | N2244: OFF-ST-10003442 | O2244: Office Supplies | P2244: Storage | Q2244: Eldon Portable Mobile Manager | R2244: 56.56 | S2244: 2 | T2244: 0 | U2244: 15.2712 | V2244: =YEAR(Orders!$C2244) -> 2017 | W2244: =TEXT(Orders!$C2244,"mmm") -> Nov | X2244: =MONTH(Orders!$C2244) -> 11 | Y2244: =IFERROR(Orders!$U2244/Orders!$R2244,0) -> 0.27 | Z2244: =Orders!$D2244-Orders!$C2244 -> 4
A2245: 2244 | B2245: CA-2017-103380 | C2245: 43060 | D2245: 43064 | E2245: Standard Class | F2245: BF-11005 | G2245: Barry Franz | H2245: Home Office | I2245: United States | J2245: Pasadena | K2245: California | L2245: 91104 | M2245: West | N2245: OFF-AR-10003856 | O2245: Office Supplies | P2245: Art | Q2245: Newell 344 | R2245: 5.56 | S2245: 2 | T2245: 0 | U2245: 1.4456 | V2245: =YEAR(Orders!$C2245) -> 2017 | W2245: =TEXT(Orders!$C2245,"mmm") -> Nov | X2245: =MONTH(Orders!$C2245) -> 11 | Y2245: =IFERROR(Orders!$U2245/Orders!$R2245,0) -> 0.26 | Z2245: =Orders!$D2245-Orders!$C2245 -> 4
A2246: 2245 | B2246: CA-2017-103380 | C2246: 43060 | D2246: 43064 | E2246: Standard Class | F2246: BF-11005 | G2246: Barry Franz | H2246: Home Office | I2246: United States | J2246: Pasadena | K2246: California | L2246: 91104 | M2246: West | N2246: OFF-FA-10004248 | O2246: Office Supplies | P2246: Fasteners | Q2246: Advantus T-Pin Paper Clips | R2246: 9.02 | S2246: 2 | T2246: 0 | U2246: 3.5178 | V2246: =YEAR(Orders!$C2246) -> 2017 | W2246: =TEXT(Orders!$C2246,"mmm") -> Nov | X2246: =MONTH(Orders!$C2246) -> 11 | Y2246: =IFERROR(Orders!$U2246/Orders!$R2246,0) -> 0.39 | Z2246: =Orders!$D2246-Orders!$C2246 -> 4
A2247: 2246 | B2247: CA-2017-103380 | C2247: 43060 | D2247: 43064 | E2247: Standard Class | F2247: BF-11005 | G2247: Barry Franz | H2247: Home Office | I2247: United States | J2247: Pasadena | K2247: California | L2247: 91104 | M2247: West | N2247: OFF-AP-10001492 | O2247: Office Supplies | P2247: Appliances | Q2247: Acco Six-Outlet Power Strip, 4' Cord Length | R2247: 8.62 | S2247: 1 | T2247: 0 | U2247: 2.2412 | V2247: =YEAR(Orders!$C2247) -> 2017 | W2247: =TEXT(Orders!$C2247,"mmm") -> Nov | X2247: =MONTH(Orders!$C2247) -> 11 | Y2247: =IFERROR(Orders!$U2247/Orders!$R2247,0) -> 0.26 | Z2247: =Orders!$D2247-Orders!$C2247 -> 4
A2248: 2247 | B2248: CA-2017-103380 | C2248: 43060 | D2248: 43064 | E2248: Standard Class | F2248: BF-11005 | G2248: Barry Franz | H2248: Home Office | I2248: United States | J2248: Pasadena | K2248: California | L2248: 91104 | M2248: West | N2248: TEC-PH-10004165 | O2248: Technology | P2248: Phones | Q2248: Mitel MiVoice 5330e IP Phone | R2248: 659.976 | S2248: 3 | T2248: 0.2 | U2248: 49.4982 | V2248: =YEAR(Orders!$C2248) -> 2017 | W2248: =TEXT(Orders!$C2248,"mmm") -> Nov | X2248: =MONTH(Orders!$C2248) -> 11 | Y2248: =IFERROR(Orders!$U2248/Orders!$R2248,0) -> 0.075 | Z2248: =Orders!$D2248-Orders!$C2248 -> 4
... A5275: 5274 | B5275: US-2016-158309 | C5275: 42700 | D5275: 42703 | E5275: First Class | F5275: PA-19060 | G5275: Pete Armstrong | H5275: Home Office | I5275: United States | J5275: Miami | K5275: Florida | L5275: 33142 | M5275: South | N5275: OFF-BI-10000145 | O5275: Office Supplies | P5275: Binders | Q5275: Zipper Ring Binder Pockets | R5275: 3.744 | S5275: 4 | T5275: 0.7 | U5275: -2.6208 | V5275: =YEAR(Orders!$C5275) -> 2016 | W5275: =TEXT(Orders!$C5275,"mmm") -> Nov | X5275: =MONTH(Orders!$C5275) -> 11 | Y5275: =IFERROR(Orders!$U5275/Orders!$R5275,0) -> -0.7 | Z5275: =Orders!$D5275-Orders!$C5275 -> 3
A5276: 5275 | B5276: CA-2015-162887 | C5276: 42315 | D5276: 42317 | E5276: Second Class | F5276: SV-20785 | G5276: Stewart Visinsky | H5276: Consumer | I5276: United States | J5276: Burlington | K5276: Vermont | L5276: 05408 | M5276: East | N5276: FUR-CH-10000595 | O5276: Furniture | P5276: Chairs | Q5276: Safco Contoured Stacking Chairs | R5276: 715.2 | S5276: 3 | T5276: 0 | U5276: 178.8 | V5276: =YEAR(Orders!$C5276) -> 2015 | W5276: =TEXT(Orders!$C5276,"mmm") -> Nov | X5276: =MONTH(Orders!$C5276) -> 11 | Y5276: =IFERROR(Orders!$U5276/Orders!$R5276,0) -> 0.25 | Z5276: =Orders!$D5276-Orders!$C5276 -> 2
A5277: 5276 | B5277: CA-2017-147333 | C5277: 43083 | D5277: 43089 | E5277: Standard Class | F5277: KL-16555 | G5277: Kelly Lampkin | H5277: Corporate | I5277: United States | J5277: Fayetteville | K5277: Arkansas | L5277: 72701 | M5277: South | N5277: TEC-AC-10004469 | O5277: Technology | P5277: Accessories | Q5277: Microsoft Sculpt Comfort Mouse | R5277: 159.8 | S5277: 4 | T5277: 0 | U5277: 70.312 | V5277: =YEAR(Orders!$C5277) -> 2017 | W5277: =TEXT(Orders!$C5277,"mmm") -> Dec | X5277: =MONTH(Orders!$C5277) -> 12 | Y5277: =IFERROR(Orders!$U5277/Orders!$R5277,0) -> 0.44 | Z5277: =Orders!$D5277-Orders!$C5277 -> 6
A5278: 5277 | B5278: CA-2017-147333 | C5278: 43083 | D5278: 43089 | E5278: Standard Class | F5278: KL-16555 | G5278: Kelly Lampkin | H5278: Corporate | I5278: United States | J5278: Fayetteville | K5278: Arkansas | L5278: 72701 | M5278: South | N5278: TEC-AC-10003038 | O5278: Technology | P5278: Accessories | Q5278: Kingston Digital DataTraveler 16GB USB 2.0 | R5278: 44.75 | S5278: 5 | T5278: 0 | U5278: 8.5025 | V5278: =YEAR(Orders!$C5278) -> 2017 | W5278: =TEXT(Orders!$C5278,"mmm") -> Dec | X5278: =MONTH(Orders!$C5278) -> 12 | Y5278: =IFERROR(Orders!$U5278/Orders!$R5278,0) -> 0.19 | Z5278: =Orders!$D5278-Orders!$C5278 -> 6
A5279: 5278 | B5279: CA-2014-113859 | C5279: 41895 | D5279: 41899 | E5279: Standard Class | F5279: BC-11125 | G5279: Becky Castell | H5279: Home Office | I5279: United States | J5279: Odessa | K5279: Texas | L5279: 79762 | M5279: Central | N5279: FUR-CH-10004698 | O5279: Furniture | P5279: Chairs | Q5279: Padded Folding Chairs, Black, 4/Carton | R5279: 340.116 | S5279: 6 | T5279: 0.3 | U5279: -9.7176 | V5279: =YEAR(Orders!$C5279) -> 2014 | W5279: =TEXT(Orders!$C5279,"mmm") -> Sep | X5279: =MONTH(Orders!$C5279) -> 9 | Y5279: =IFERROR(Orders!$U5279/Orders!$R5279,0) -> -0.028571429 | Z5279: =Orders!$D5279-Orders!$C5279 -> 4
A5280: 5279 | B5280: CA-2014-159681 | C5280: 41980 | D5280: 41986 | E5280: Standard Class | F5280: PO-18850 | G5280: Patrick O'Brill | H5280: Consumer | I5280: United States | J5280: Virginia Beach | K5280: Virginia | L5280: 23464 | M5280: South | N5280: OFF-PA-10003641 | O5280: Office Supplies | P5280: Paper | Q5280: Xerox 1909 | R5280: 105.52 | S5280: 4 | T5280: 0 | U5280: 48.5392 | V5280: =YEAR(Orders!$C5280) -> 2014 | W5280: =TEXT(Orders!$C5280,"mmm") -> Dec | X5280: =MONTH(Orders!$C5280) -> 12 | Y5280: =IFERROR(Orders!$U5280/Orders!$R5280,0) -> 0.46 | Z5280: =Orders!$D5280-Orders!$C5280 -> 6
A5281: 5280 | B5281: US-2017-104094 | C5281: 42985 | D5281: 42989 | E5281: Standard Class | F5281: AG-10675 | G5281: Anna Gayman | H5281: Consumer | I5281: United States | J5281: Milwaukee | K5281: Wisconsin | L5281: 53209 | M5281: Central | N5281: TEC-AC-10002134 | O5281: Technology | P5281: Accessories | Q5281: Rosewill 107 Normal Keys USB Wired Standard Keyboard | R5281: 13.48 | S5281: 1 | T5281: 0 | U5281: 1.8872 | V5281: =YEAR(Orders!$C5281) -> 2017 | W5281: =TEXT(Orders!$C5281,"mmm") -> Sep | X5281: =MONTH(Orders!$C5281) -> 9 | Y5281: =IFERROR(Orders!$U5281/Orders!$R5281,0) -> 0.14 | Z5281: =Orders!$D5281-Orders!$C5281 -> 4
A5282: 5281 | B5282: CA-2017-152709 | C5282: 43015 | D5282: 43020 | E5282: Standard Class | F5282: DB-13210 | G5282: Dean Braden | H5282: Consumer | I5282: United States | J5282: Detroit | K5282: Michigan | L5282: 48234 | M5282: Central | N5282: OFF-ST-10001837 | O5282: Office Supplies | P5282: Storage | Q5282: SAFCO Mobile Desk Side File, Wire Frame | R5282: 85.52 | S5282: 2 | T5282: 0 | U5282: 22.2352 | V5282: =YEAR(Orders!$C5282) -> 2017 | W5282: =TEXT(Orders!$C5282,"mmm") -> Oct | X5282: =MONTH(Orders!$C5282) -> 10 | Y5282: =IFERROR(Orders!$U5282/Orders!$R5282,0) -> 0.26 | Z5282: =Orders!$D5282-Orders!$C5282 -> 5
A5283: 5282 | B5283: CA-2015-105158 | C5283: 42252 | D5283: 42257 | E5283: Standard Class | F5283: SP-20860 | G5283: Sung Pak | H5283: Corporate | I5283: United States | J5283: Rochester | K5283: Minnesota | L5283: 55901 | M5283: Central | N5283: FUR-FU-10001706 | O5283: Furniture | P5283: Furnishings | Q5283: Longer-Life Soft White Bulbs | R5283: 6.16 | S5283: 2 | T5283: 0 | U5283: 2.9568 | V5283: =YEAR(Orders!$C5283) -> 2015 | W5283: =TEXT(Orders!$C5283,"mmm") -> Sep | X5283: =MONTH(Orders!$C5283) -> 9 | Y5283: =IFERROR(Orders!$U5283/Orders!$R5283,0) -> 0.48 | Z5283: =Orders!$D5283-Orders!$C5283 -> 5
A5284: 5283 | B5284: CA-2015-105158 | C5284: 42252 | D5284: 42257 | E5284: Standard Class | F5284: SP-20860 | G5284: Sung Pak | H5284: Corporate | I5284: United States | J5284: Rochester | K5284: Minnesota | L5284: 55901 | M5284: Central | N5284: OFF-PA-10001970 | O5284: Office Supplies | P5284: Paper | Q5284: Xerox 1881 | R5284: 36.84 | S5284: 3 | T5284: 0 | U5284: 17.3148 | V5284: =YEAR(Orders!$C5284) -> 2015 | W5284: =TEXT(Orders!$C5284,"mmm") -> Sep | X5284: =MONTH(Orders!$C5284) -> 9 | Y5284: =IFERROR(Orders!$U5284/Orders!$R5284,0) -> 0.47 | Z5284: =Orders!$D5284-Orders!$C5284 -> 5
A5285: 5284 | B5285: CA-2014-133424 | C5285: 41728 | D5285: 41733 | E5285: Standard Class | F5285: Dl-13600 | G5285: Dorris liebe | H5285: Corporate | I5285: United States | J5285: Seattle | K5285: Washington | L5285: 98105 | M5285: West | N5285: OFF-ST-10002957 | O5285: Office Supplies | P5285: Storage | Q5285: Sterilite Show Offs Storage Containers | R5285: 15.84 | S5285: 3 | T5285: 0 | U5285: 0 | V5285: =YEAR(Orders!$C5285) -> 2014 | W5285: =TEXT(Orders!$C5285,"mmm") -> Mar | X5285: =MONTH(Orders!$C5285) -> 3 | Y5285: =IFERROR(Orders!$U5285/Orders!$R5285,0) -> 0 | Z5285: =Orders!$D5285-Orders!$C5285 -> 5
A5286: 5285 | B5286: CA-2014-133424 | C5286: 41728 | D5286: 41733 | E5286: Standard Class | F5286: Dl-13600 | G5286: Dorris liebe | H5286: Corporate | I5286: United States | J5286: Seattle | K5286: Washington | L5286: 98105 | M5286: West | N5286: OFF-LA-10002312 | O5286: Office Supplies | P5286: Labels | Q5286: Avery 490 | R5286: 44.4 | S5286: 3 | T5286: 0 | U5286: 22.2 | V5286: =YEAR(Orders!$C5286) -> 2014 | W5286: =TEXT(Orders!$C5286,"mmm") -> Mar | X5286: =MONTH(Orders!$C5286) -> 3 | Y5286: =IFERROR(Orders!$U5286/Orders!$R5286,0) -> 0.5 | Z5286: =Orders!$D5286-Orders!$C5286 -> 5
A5287: 5286 | B5287: CA-2017-105991 | C5287: 42860 | D5287: 42861 | E5287: First Class | F5287: LH-17020 | G5287: Lisa Hazard | H5287: Consumer | I5287: United States | J5287: Louisville | K5287: Colorado | L5287: 80027 | M5287: West | N5287: OFF-EN-10002600 | O5287: Office Supplies | P5287: Envelopes | Q5287: Redi-Strip #10 Envelopes, 4 1/8 x 9 1/2 | R5287: 21.24 | S5287: 9 | T5287: 0.2 | U5287: 7.434 | V5287: =YEAR(Orders!$C5287) -> 2017 | W5287: =TEXT(Orders!$C5287,"mmm") -> May | X5287: =MONTH(Orders!$C5287) -> 5 | Y5287: =IFERROR(Orders!$U5287/Orders!$R5287,0) -> 0.35 | Z5287: =Orders!$D5287-Orders!$C5287 -> 1
...

Sheet Data Quality
A1: Check | B1: Result
A2: Sales | B2: =COUNTBLANK(Orders!$R$2:$R$9995) -> 0
A3: Profit | B3: =COUNTBLANK(Orders!$U$2:$U$9995) -> 0
A4: Order Date | B4: =COUNTBLANK(Orders!$C$2:$C$9995) -> 0
A5: Product Name | B5: =COUNTBLANK(Orders!$Q$2:$Q$9995) -> 0
A6: Category | B6: =COUNTBLANK(Orders!$O$2:$O$9995) -> 0
A8: Earliest Order Date | B8: =MIN(Orders!$C$2:$C$9995) -> 41642
A9: Latest Order Date | B9: =MAX(Orders!$C$2:$C$9995) -> 43099
A11: Sales Check
A12: Minimum Sales | B12: =MIN(Orders!$R$2:$R$9995) -> 0.444
A13: Maximum Sales | B13: =MAX(Orders!$R$2:$R$9995) -> 22638.48
A14: Average Sales | B14: =AVERAGE(Orders!$R$2:$R$9995) -> 229.858
A16: Quantity Check
A17: Minimum Quantity | B17: =MIN(Orders!$S$2:$S$9995) -> 1
A18: Maximum Quantity | B18: =MAX(Orders!$S$2:$S$9995) -> 14
A19: Average Quantity | B19: =AVERAGE(Orders!$S$2:$S$9995) -> 3.7895737
A21: Discount Check
A22: Minimum Discount | B22: =MIN(Orders!$T$2:$T$9995) -> 0
A23: Maximum Discount | B23: =MAX(Orders!$T$2:$T$9995) -> 0.8
A24: Average Discount | B24: =AVERAGE(Orders!$T$2:$T$9995) -> 0.15620272
A26: Profit Check
A27: Minimum Profit | B27: =MIN(Orders!$U$2:$U$9995) -> -6599.978
A28: Maximum Profit | B28: =MAX(Orders!$U$2:$U$9995) -> 8399.976
A29: Average Profit | B29: =AVERAGE(Orders!$U$2:$U$9995) -> 28.656896

Sheet Analysis
A1: SALES PERFORMANCE DASHBOARD
A3: Total Sales | B3: =SUM(Orders!$R$2:$R$9995) -> 2297200.9
A4: Total Profit | B4: =SUM(Orders!$U$2:$U$9995) -> 286397.02
A5: Total Orders | B5: =COUNTA(_xlfn.UNIQUE(Orders!$B$2:$B$9995)) -> 5009
A6: Average Order Value | B6: =B3/B5 -> 458.61467
A7: Profit Margin | B7: =B4/B3 -> 0.12467217
A10: Sum of Sales
A11: Order Year | B11: Total
A12: 2014 | B12: 484247.5
A13: 2015 | B13: 470532.51
A14: 2016 | B14: 609205.6
A15: 2017 | B15: 733215.26
A16: Grand Total | B16: 2297200.9
A25: Sum of Sales
A26: Category | B26: Total
A27: Furniture | B27: 741999.8
A28: Office Supplies | B28: 719047.03
A29: Technology | B29: 836154.03
A30: Grand Total | B30: 2297200.9
A40: Sum of Sales
A41: Region | B41: Total
A42: Central | B42: 501239.89
A43: East | B43: 678781.24
A44: South | B44: 391721.91
A45: West | B45: 725457.82
A46: Grand Total | B46: 2297200.9
A55: Sum of Sales
A56: Segment | B56: Total
A57: Consumer | B57: 1161401.3
A58: Corporate | B58: 706146.37
A59: Home Office | B59: 429653.15
A60: Grand Total | B60: 2297200.9
A70: Sum of Sales
A71: Sub-Category | B71: Total
A72: Accessories | B72: 167380.32
A73: Appliances | B73: 107532.16
A74: Art | B74: 27118.792
A75: Binders | B75: 203412.73
A76: Bookcases | B76: 114880
A77: Chairs | B77: 328449.1
...

Sheet Returns
A1: Returned | B1: Order ID
A2: Yes | B2: CA-2017-153822
A3: Yes | B3: CA-2017-129707
A4: Yes | B4: CA-2014-152345
A5: Yes | B5: CA-2015-156440
A6: Yes | B6: US-2017-155999
A7: Yes | B7: CA-2014-157924
A8: Yes | B8: CA-2017-131807
A9: Yes | B9: CA-2016-124527
A10: Yes | B10: CA-2017-135692
A11: Yes | B11: CA-2014-123225
A12: Yes | B12: CA-2017-145772
... A297: Yes | B297: CA-2015-149636

Sheet People
A1: Person | B1: Region
A2: Anna Andreadi | B2: West
A3: Chuck Magee | B3: East
A4: Kelly Williams | B4: Central
A5: Cassandra Brandow | B5: South
